<?xml version="1.0" encoding="UTF-8"?>
<!-- Generated by org.testng.reporters.JUnitReportReporter -->
<testsuite hostname="Developer-205" name="com.rabbitrewards.testcase.mydetail.Update_Customer_All_Details_005" tests="6" failures="0" timestamp="26 Apr 2016 02:04:28 GMT" time="66.008" errors="3">
  <testcase name="rewardsLogin" time="17.100" classname="com.rabbitrewards.testcase.mydetail.Update_Customer_All_Details_005"/>
  <testcase name="staticValidationMyDetail" time="0.000" classname="com.rabbitrewards.testcase.mydetail.Update_Customer_All_Details_005">
    <error type="java.lang.Throwable" message="Method Update_Customer_All_Details_005.staticValidationMyDetail()[pri:0, instance:com.rabbitrewards.testcase.mydetail.Update_Customer_All_Details_005@69a3d1d] depends on not successfully finished methods">
      <![CDATA[java.lang.Throwable: Method Update_Customer_All_Details_005.staticValidationMyDetail()[pri:0, instance:com.rabbitrewards.testcase.mydetail.Update_Customer_All_Details_005@69a3d1d] depends on not successfully finished methods
	at org.testng.internal.Invoker.invokeTestMethods(Invoker.java:1063)
	at org.testng.internal.TestMethodWorker.invokeTestMethods(TestMethodWorker.java:125)
	at org.testng.internal.TestMethodWorker.run(TestMethodWorker.java:108)
	at org.testng.TestRunner.privateRun(TestRunner.java:771)
	at org.testng.TestRunner.run(TestRunner.java:621)
	at org.testng.SuiteRunner.runTest(SuiteRunner.java:357)
	at org.testng.SuiteRunner.runSequentially(SuiteRunner.java:352)
	at org.testng.SuiteRunner.privateRun(SuiteRunner.java:310)
	at org.testng.SuiteRunner.run(SuiteRunner.java:259)
	at org.testng.SuiteRunnerWorker.runSuite(SuiteRunnerWorker.java:52)
	at org.testng.SuiteRunnerWorker.run(SuiteRunnerWorker.java:86)
	at org.testng.TestNG.runSuitesSequentially(TestNG.java:1199)
	at org.testng.TestNG.runSuitesLocally(TestNG.java:1124)
	at org.testng.TestNG.run(TestNG.java:1032)
	at org.testng.remote.AbstractRemoteTestNG.run(AbstractRemoteTestNG.java:126)
	at org.testng.remote.RemoteTestNG.initAndRun(RemoteTestNG.java:137)
	at org.testng.remote.RemoteTestNG.main(RemoteTestNG.java:58)
]]>
    </error>
  </testcase> <!-- staticValidationMyDetail -->
  <testcase name="updateExisitingCustomerDetails" time="35.968" classname="com.rabbitrewards.testcase.mydetail.Update_Customer_All_Details_005"/>
  <testcase name="rewardsLogin_2" time="10.711" classname="com.rabbitrewards.testcase.mydetail.Update_Customer_All_Details_005">
    <error type="com.automation.framework.exception.BusinessException" message="Found Fail Step From Update_Customer_All_Details_005">
      <![CDATA[com.automation.framework.exception.BusinessException: Found Fail Step From Update_Customer_All_Details_005
	at com.automation.framework.util.Test.checkFail(Test.java:526)
	at com.automation.framework.util.Test.script(Test.java:197)
	at com.automation.framework.util.Test.script(Test.java:186)
	at com.rabbitbase.generic.Generic_Rewards.rewardsMainLogin(Generic_Rewards.java:58)
	at com.rabbitbase.generic.Generic_Rewards.rewardsLogin(Generic_Rewards.java:38)
	at com.rabbitrewards.testcase.mydetail.Update_Customer_All_Details_005.rewardsLogin_2(Update_Customer_All_Details_005.java:51)
	at sun.reflect.NativeMethodAccessorImpl.invoke0(Native Method)
	at sun.reflect.NativeMethodAccessorImpl.invoke(NativeMethodAccessorImpl.java:62)
	at sun.reflect.DelegatingMethodAccessorImpl.invoke(DelegatingMethodAccessorImpl.java:43)
	at java.lang.reflect.Method.invoke(Method.java:498)
	at org.testng.internal.MethodInvocationHelper.invokeMethod(MethodInvocationHelper.java:85)
	at org.testng.internal.Invoker.invokeMethod(Invoker.java:659)
	at org.testng.internal.Invoker.invokeTestMethod(Invoker.java:845)
	at org.testng.internal.Invoker.invokeTestMethods(Invoker.java:1153)
	at org.testng.internal.TestMethodWorker.invokeTestMethods(TestMethodWorker.java:125)
	at org.testng.internal.TestMethodWorker.run(TestMethodWorker.java:108)
	at org.testng.TestRunner.privateRun(TestRunner.java:771)
	at org.testng.TestRunner.run(TestRunner.java:621)
	at org.testng.SuiteRunner.runTest(SuiteRunner.java:357)
	at org.testng.SuiteRunner.runSequentially(SuiteRunner.java:352)
	at org.testng.SuiteRunner.privateRun(SuiteRunner.java:310)
	at org.testng.SuiteRunner.run(SuiteRunner.java:259)
	at org.testng.SuiteRunnerWorker.runSuite(SuiteRunnerWorker.java:52)
	at org.testng.SuiteRunnerWorker.run(SuiteRunnerWorker.java:86)
	at org.testng.TestNG.runSuitesSequentially(TestNG.java:1199)
	at org.testng.TestNG.runSuitesLocally(TestNG.java:1124)
	at org.testng.TestNG.run(TestNG.java:1032)
	at org.testng.remote.AbstractRemoteTestNG.run(AbstractRemoteTestNG.java:126)
	at org.testng.remote.RemoteTestNG.initAndRun(RemoteTestNG.java:137)
	at org.testng.remote.RemoteTestNG.main(RemoteTestNG.java:58)
]]>
    </error>
  </testcase> <!-- rewardsLogin_2 -->
  <testcase name="rewardsSignOut_1" time="2.229" classname="com.rabbitrewards.testcase.mydetail.Update_Customer_All_Details_005"/>
  <testcase name="rewardsSignOut_2" time="0.000" classname="com.rabbitrewards.testcase.mydetail.Update_Customer_All_Details_005">
    <error type="java.lang.Throwable" message="Method Update_Customer_All_Details_005.rewardsSignOut_2()[pri:0, instance:com.rabbitrewards.testcase.mydetail.Update_Customer_All_Details_005@69a3d1d] depends on not successfully finished methods">
      <![CDATA[java.lang.Throwable: Method Update_Customer_All_Details_005.rewardsSignOut_2()[pri:0, instance:com.rabbitrewards.testcase.mydetail.Update_Customer_All_Details_005@69a3d1d] depends on not successfully finished methods
	at org.testng.internal.Invoker.invokeTestMethods(Invoker.java:1063)
	at org.testng.internal.TestMethodWorker.invokeTestMethods(TestMethodWorker.java:125)
	at org.testng.internal.TestMethodWorker.run(TestMethodWorker.java:108)
	at org.testng.TestRunner.privateRun(TestRunner.java:771)
	at org.testng.TestRunner.run(TestRunner.java:621)
	at org.testng.SuiteRunner.runTest(SuiteRunner.java:357)
	at org.testng.SuiteRunner.runSequentially(SuiteRunner.java:352)
	at org.testng.SuiteRunner.privateRun(SuiteRunner.java:310)
	at org.testng.SuiteRunner.run(SuiteRunner.java:259)
	at org.testng.SuiteRunnerWorker.runSuite(SuiteRunnerWorker.java:52)
	at org.testng.SuiteRunnerWorker.run(SuiteRunnerWorker.java:86)
	at org.testng.TestNG.runSuitesSequentially(TestNG.java:1199)
	at org.testng.TestNG.runSuitesLocally(TestNG.java:1124)
	at org.testng.TestNG.run(TestNG.java:1032)
	at org.testng.remote.AbstractRemoteTestNG.run(AbstractRemoteTestNG.java:126)
	at org.testng.remote.RemoteTestNG.initAndRun(RemoteTestNG.java:137)
	at org.testng.remote.RemoteTestNG.main(RemoteTestNG.java:58)
]]>
    </error>
  </testcase> <!-- rewardsSignOut_2 -->
</testsuite> <!-- com.rabbitrewards.testcase.mydetail.Update_Customer_All_Details_005 -->
