<?xml version="1.0" encoding="UTF-8"?>
<!-- Generated by org.testng.reporters.JUnitReportReporter -->
<testsuite hostname="Developer-205" name="com.rabbitrewards.testcase.mydetail.Update_Customer_Shipping_Same_Home_006" tests="6" failures="0" timestamp="26 Apr 2016 03:02:46 GMT" time="140.971" errors="2">
  <testcase name="staticValidationMyDetail" time="60.829" classname="com.rabbitrewards.testcase.mydetail.Update_Customer_Shipping_Same_Home_006">
    <error type="com.automation.framework.exception.BusinessException" message="Validation of Shipping Add. Province
	Fail -  ACTUAL VALUE: &#039;Select&#039;
		EXPECT VALUE: &#039;Loei&#039;">
      <![CDATA[com.automation.framework.exception.BusinessException: Validation of Shipping Add. Province
	Fail -  ACTUAL VALUE: 'Select'
		EXPECT VALUE: 'Loei'
	at com.automation.framework.util.Test.comparisonResult(Test.java:687)
	at com.automation.framework.util.Test.staticValidateSelectList(Test.java:709)
	at com.rabbitrewards.testscript.MyDetail.staticValidationShippingAddress(MyDetail.java:307)
	at com.rabbitrewards.testscript.MyDetail.staticValidationUpdateDetails(MyDetail.java:135)
	at com.rabbitrewards.testcase.mydetail.Update_Customer_Shipping_Same_Home_006.staticValidationMyDetail(Update_Customer_Shipping_Same_Home_006.java:59)
	at sun.reflect.NativeMethodAccessorImpl.invoke0(Native Method)
	at sun.reflect.NativeMethodAccessorImpl.invoke(NativeMethodAccessorImpl.java:62)
	at sun.reflect.DelegatingMethodAccessorImpl.invoke(DelegatingMethodAccessorImpl.java:43)
	at java.lang.reflect.Method.invoke(Method.java:498)
	at org.testng.internal.MethodInvocationHelper.invokeMethod(MethodInvocationHelper.java:85)
	at org.testng.internal.Invoker.invokeMethod(Invoker.java:659)
	at org.testng.internal.Invoker.invokeTestMethod(Invoker.java:845)
	at org.testng.internal.Invoker.invokeTestMethods(Invoker.java:1153)
	at org.testng.internal.TestMethodWorker.invokeTestMethods(TestMethodWorker.java:125)
	at org.testng.internal.TestMethodWorker.run(TestMethodWorker.java:108)
	at org.testng.TestRunner.privateRun(TestRunner.java:771)
	at org.testng.TestRunner.run(TestRunner.java:621)
	at org.testng.SuiteRunner.runTest(SuiteRunner.java:357)
	at org.testng.SuiteRunner.runSequentially(SuiteRunner.java:352)
	at org.testng.SuiteRunner.privateRun(SuiteRunner.java:310)
	at org.testng.SuiteRunner.run(SuiteRunner.java:259)
	at org.testng.SuiteRunnerWorker.runSuite(SuiteRunnerWorker.java:52)
	at org.testng.SuiteRunnerWorker.run(SuiteRunnerWorker.java:86)
	at org.testng.TestNG.runSuitesSequentially(TestNG.java:1199)
	at org.testng.TestNG.runSuitesLocally(TestNG.java:1124)
	at org.testng.TestNG.run(TestNG.java:1032)
	at org.testng.remote.AbstractRemoteTestNG.run(AbstractRemoteTestNG.java:126)
	at org.testng.remote.RemoteTestNG.initAndRun(RemoteTestNG.java:137)
	at org.testng.remote.RemoteTestNG.main(RemoteTestNG.java:58)
]]>
    </error>
  </testcase> <!-- staticValidationMyDetail -->
  <testcase name="rewardsSignOut_2" time="0.000" classname="com.rabbitrewards.testcase.mydetail.Update_Customer_Shipping_Same_Home_006">
    <error type="java.lang.Throwable" message="Method Update_Customer_Shipping_Same_Home_006.rewardsSignOut_2()[pri:0, instance:com.rabbitrewards.testcase.mydetail.Update_Customer_Shipping_Same_Home_006@6c40365c] depends on not successfully finished methods">
      <![CDATA[java.lang.Throwable: Method Update_Customer_Shipping_Same_Home_006.rewardsSignOut_2()[pri:0, instance:com.rabbitrewards.testcase.mydetail.Update_Customer_Shipping_Same_Home_006@6c40365c] depends on not successfully finished methods
	at org.testng.internal.Invoker.invokeTestMethods(Invoker.java:1063)
	at org.testng.internal.TestMethodWorker.invokeTestMethods(TestMethodWorker.java:125)
	at org.testng.internal.TestMethodWorker.run(TestMethodWorker.java:108)
	at org.testng.TestRunner.privateRun(TestRunner.java:771)
	at org.testng.TestRunner.run(TestRunner.java:621)
	at org.testng.SuiteRunner.runTest(SuiteRunner.java:357)
	at org.testng.SuiteRunner.runSequentially(SuiteRunner.java:352)
	at org.testng.SuiteRunner.privateRun(SuiteRunner.java:310)
	at org.testng.SuiteRunner.run(SuiteRunner.java:259)
	at org.testng.SuiteRunnerWorker.runSuite(SuiteRunnerWorker.java:52)
	at org.testng.SuiteRunnerWorker.run(SuiteRunnerWorker.java:86)
	at org.testng.TestNG.runSuitesSequentially(TestNG.java:1199)
	at org.testng.TestNG.runSuitesLocally(TestNG.java:1124)
	at org.testng.TestNG.run(TestNG.java:1032)
	at org.testng.remote.AbstractRemoteTestNG.run(AbstractRemoteTestNG.java:126)
	at org.testng.remote.RemoteTestNG.initAndRun(RemoteTestNG.java:137)
	at org.testng.remote.RemoteTestNG.main(RemoteTestNG.java:58)
]]>
    </error>
  </testcase> <!-- rewardsSignOut_2 -->
  <testcase name="rewardsLogin" time="23.741" classname="com.rabbitrewards.testcase.mydetail.Update_Customer_Shipping_Same_Home_006"/>
  <testcase name="rewardsLogin_2" time="21.083" classname="com.rabbitrewards.testcase.mydetail.Update_Customer_Shipping_Same_Home_006"/>
  <testcase name="updateExisitingCustomerDetails" time="33.007" classname="com.rabbitrewards.testcase.mydetail.Update_Customer_Shipping_Same_Home_006"/>
  <testcase name="rewardsSignOut_1" time="2.311" classname="com.rabbitrewards.testcase.mydetail.Update_Customer_Shipping_Same_Home_006"/>
</testsuite> <!-- com.rabbitrewards.testcase.mydetail.Update_Customer_Shipping_Same_Home_006 -->
